<?xml version="1.0"?>
<robot name="aux1">
  <link name="root">
    <inertial>
      <mass value="0.0"/>
      <inertia ixx="0.0" ixy="0.0" ixz="0.0" iyy="0.0" iyz="0.0" izz="0.0"/>
    </inertial>
  </link>
  <joint name="root_aux" type="prismatic">
    <origin xyz="0 0 0" rpy="0 0 0"/>
    <parent link="root"/>
    <child link="aux"/>
    <axis xyz="1 0 0"/>
    <limit effort="100" velocity="3.0" lower="-0.08" upper="0.08"/>
  </joint>
  <link name="aux">
    <inertial>
      <mass value="0.0"/>
      <inertia ixx="0.0" ixy="0.0" ixz="0.0" iyy="0.0" iyz="0.0" izz="0.0"/>
    </inertial>
  </link>
  <joint name="aux_aux1" type="prismatic">
    <origin xyz="0 0 0" rpy="0 0 0"/>
    <parent link="aux"/>
    <child link="aux1"/>
    <axis xyz="0 1 0"/>
    <limit effort="100" velocity="3.0" lower="-0.08" upper="0.08"/>
  </joint>
  <link name="aux1">
    <inertial>
      <mass value="0.0"/>
      <inertia ixx="0.0" ixy="0.0" ixz="0.0" iyy="0.0" iyz="0.0" izz="0.0"/>
    </inertial>
  </link>
  <joint name="aux1_ball" type="prismatic">
    <origin xyz="0 0 0" rpy="0 0 0"/>
    <parent link="aux1"/>
    <child link="ball"/>
    <axis xyz="0 0 1"/>
    <limit effort="100" velocity="3.0" lower="0.07" upper="0.13"/>
  </joint>
  <link name="ball">
    <visual>
      <origin xyz="0 0 0"/>
      <geometry>
        <sphere radius="0.01"/>
      </geometry>
    </visual>
    <collision>
      <origin xyz="0 0 0"/>
      <geometry>
        <sphere radius="0.008"/>
      </geometry>
    </collision>
    <inertial>
      <mass value="0.5"/>
      <inertia ixx="0.01" ixy="0.0" ixz="0.0" iyy="0.01" iyz="0.0" izz="0.01"/>
    </inertial>
  </link>
</robot>
